Workbook

Sheet GeneralSbs
A1: Index | B1: Name | C1: Group | D1: Sex | E1: Weight1 | F1: Weight2 | G1: Height1 | H1: Height2 | I1: WPX_1J1 | J1: WPX_1J2 | K1: Step_Width_1J_11 | L1: Step_Width_1J_12 | M1: Step_Width_1J_21 | N1: Step_Width_1J_22 | O1: TFlight_1J1 | P1: TFlight_1J2 | Q1: Elevation_1J1 | R1: Elevation_1J2 | S1: Jumps1 | T1: Jumps2 | U1: TFlight1 | V1: TFlight2 | W1: TContact1 | X1: TContact2 | Y1: Elevation1 | Z1: Elevation2 | AA1: Power1 | AB1: Power2 | AC1: Pace1 | AD1: Pace2 | AE1: RSI1 | AF1: RSI2 | AG1: WPX1 | AH1: WPX2 | AI1: WPY1 | AJ1: WPY2 | AK1: Step_Width1 | AL1: Step_Width2 | AM1: Distance1 | AN1: Distance2 | AO1: TTotal_Sum1 | AP1: TTotal_Sum2 | AQ1: TTotal_Avg1 | AR1: TTotal_Avg2 | AS1: Slope_TF1 | AT1: Slope_TF2 | AU1: Slope_TC1 | AV1: Slope_TC2 | AW1: Slope_E1 | AX1: Slope_E2 | AY1: Slope_Pw1 | AZ1: Slope_Pw2 | BA1: Slope_Pace1 | BB1: Slope_Pace2 | BC1: Slope_RSI1 | BD1: Slope_RSI2 | BE1: Slope_Step_Width1 | BF1: Slope_Step_Width2 | BG1: Slope_Distance1 | BH1: Slope_Distance2 | BI1: Bosco_TFlight1 | BJ1: Bosco_TFlight2 | BK1: Bosco_TContact1 | BL1: Bosco_TContact2 | BM1: Bosco_Elevation1 | BN1: Bosco_Elevation2 | BO1: Bosco_Power1 | BP1: Bosco_Power2 | BQ1: Bosco_Pace1 | BR1: Bosco_Pace2 | BS1: Bosco_RSI1 | BT1: Bosco_RSI2 | BU1: Bosco_Step_Width1 | BV1: Bosco_Step_Width2 | BW1: Bosco_Distance1 | BX1: Bosco_Distance2
A2: 1 | B2: o1 | C2: J | D2: F | E2: 69 | F2: 69 | G2: 158 | H2: 158 | I2: 1.1 | J2: -0.5 | K2: 24 | L2: 24 | M2: 27.1 | N2: 27.1 | O2: 0.396 | P2: 0.369 | Q2: 19.2 | R2: 16.7 | S2: 122 | T2: 124 | U2: 0.18412295 | V2: 0.16104839 | W2: 0.30944628 | X2: 0.32708943 | Y2: 4.3245902 | Z2: 3.2741935 | AA2: 7.4688274 | AB2: 5.8460016 | AC2: 2.0526649 | AD2: 2.0547325 | AE2: 0.15572703 | AF2: 0.10117561 | AG2: 10.163636 | AH2: 10.243902 | AI2: 2.9793388 | AJ2: 11.03252 | AK2: 501.20164 | AL2: 476.27177 | AM2: 5.5264096 | AN2: 4.4966563 | AO2: 59.906 | AP2: 60.202 | AQ2: 0.49103279 | AR2: 0.4855 | AS2: =SLOPE(TFlight!G2:FR2,TPoints!G2:FR2) -> -0.0012364034 | AT2: =SLOPE(TFlight!G42:FR42,TPoints!G42:FR42) -> -0.0012670095 | AU2: =SLOPE(TContact!H2:FR2,TPoints!H2:FR2) -> 0.00026183766 | AV2: =SLOPE(TContact!H42:FR42,TPoints!H42:FR42) -> 0.00072463097 | AW2: =SLOPE(Elevation!G2:FR2,TPoints!G2:FR2) -> -0.057057162 | AX2: =SLOPE(Elevation!G42:FR42,TPoints!G42:FR42) -> -0.049776713 | AY2: =SLOPE(Power!H2:FR2,TPoints!H2:FR2) -> -0.069713536 | AZ2: =SLOPE(Power!H42:FR42,TPoints!H42:FR42) -> -0.063518209 | BA2: =SLOPE(Pace!H2:FR2,TPoints!H2:FR2) -> 0.0036433542 | BB2: =SLOPE(Pace!H42:FR42,TPoints!H42:FR42) -> 0.0022314602 | BC2: =SLOPE(RSI!H2:FR2,TPoints!H2:FR2) -> -0.0020763793 | BD2: =SLOPE(RSI!H42:FR42,TPoints!H42:FR42) -> -0.0017175797 | BE2: =SLOPE(StepWidth!G2:FR2,TPoints!G2:FR2) -> -1.481837 | BF2: =SLOPE(StepWidth!G42:FR42,TPoints!G42:FR42) -> 0.90641361 | BG2: =SLOPE(Distance!H2:FR2,TPoints!H2:FR2) -> -0.042946386 | BH2: =SLOPE(Distance!H42:FR42,TPoints!H42:FR42) -> -0.017482676 | BI2: =100*(MAX(TFlight!G2:FR2)-MIN(TFlight!G2:FR2))/MAX(TFlight!G2:FR2) -> 74.948665 | BJ2: =100*(MAX(TFlight!G42:FR42)-MIN(TFlight!G42:FR42))/MAX(TFlight!G42:FR42) -> 60.683761 | BK2: =100*(MAX(TContact!H2:FR2)-MIN(TContact!H2:FR2))/MAX(TContact!H2:FR2) -> 95.05814 | BL2: =100*(MAX(TContact!H42:FR42)-MIN(TContact!H42:FR42))/MAX(TContact!H42:FR42) -> 29.081633 | BM2: =100*(MAX(Elevation!G2:FR2)-MIN(Elevation!G2:FR2))/MAX(Elevation!G2:FR2) -> 93.814433 | BN2: =100*(MAX(Elevation!G42:FR42)-MIN(Elevation!G42:FR42))/MAX(Elevation!G42:FR42) -> 85.074627 | BO2: =100*(MAX(Power!H2:FR2)-MIN(Power!H2:FR2))/MAX(Power!H2:FR2) -> 91.533225 | BP2: =100*(MAX(Power!H42:FR42)-MIN(Power!H42:FR42))/MAX(Power!H42:FR42) -> 70.429054 | BQ2: =100*(MAX(Pace!H2:FR2)-MIN(Pace!H2:FR2))/MAX(Pace!H2:FR2) -> 76.448829 | BR2: =100*(MAX(Pace!H42:FR42)-MIN(Pace!H42:FR42))/MAX(Pace!H42:FR42) -> 18.35206 | BS2: =100*(MAX(RSI!H2:FR2)-MIN(RSI!H2:FR2))/MAX(RSI!H2:FR2) -> 97.581792 | BT2: =100*(MAX(RSI!H42:FR42)-MIN(RSI!H42:FR42))/MAX(RSI!H42:FR42) -> 86.143411 | BU2: =100*(MAX(StepWidth!G2:FR2)-MIN(StepWidth!G2:FR2))/MAX(StepWidth!G2:FR2) -> 84.515746 | BV2: =100*(MAX(StepWidth!G42:FR42)-MIN(StepWidth!G42:FR42))/MAX(StepWidth!G42:FR42) -> 61.673062 | BW2: =100*(MAX(Distance!H2:FR2)-MIN(Distance!H2:FR2))/MAX(Distance!H2:FR2) -> 94.867406 | BX2: =100*(MAX(Distance!H42:FR42)-MIN(Distance!H42:FR42))/MAX(Distance!H42:FR42) -> 100
A3: 2 | B3: o2 | C3: B | D3: M | E3: 70 | F3: 70 | G3: 157 | H3: 157 | I3: 0 | J3: -5.7 | K3: 0 | L3: 30.2 | M3: 42.7 | N3: 32.3 | O3: 0.348 | P3: 0.434 | Q3: 14.8 | R3: 23.1 | S3: 135 | T3: 155 | U3: 0.18534815 | V3: 0.11282581 | W3: 0.26132836 | X3: 0.27651948 | Y3: 4.3511111 | Z3: 1.6064516 | AA3: 7.7648689 | AB3: 3.8734844 | AC3: 2.247888 | AD3: 2.5726713 | AE3: 0.16911416 | AF3: 0.058829085 | AG3: 3.9529851 | AH3: 2.3987013 | AI3: 7.0470149 | AJ3: 14.648052 | AK3: 778.53926 | AL3: 853.12323 | AM3: 7.5052544 | AN3: 2.7151638 | AO3: 60.04 | AP3: 60.072 | AQ3: 0.44474074 | AR3: 0.38756129 | AS3: =SLOPE(TFlight!G3:FR3,TPoints!G3:FR3) -> -0.0014249813 | AT3: =SLOPE(TFlight!G43:FR43,TPoints!G43:FR43) -> -0.00071513662 | AU3: =SLOPE(TContact!H3:FR3,TPoints!H3:FR3) -> 0.00038717841 | AV3: =SLOPE(TContact!H43:FR43,TPoints!H43:FR43) -> 0.00014625034 | AW3: =SLOPE(Elevation!G3:FR3,TPoints!G3:FR3) -> -0.067642414 | AX3: =SLOPE(Elevation!G43:FR43,TPoints!G43:FR43) -> -0.019710871 | AY3: =SLOPE(Power!H3:FR3,TPoints!H3:FR3) -> -0.092408945 | AZ3: =SLOPE(Power!H43:FR43,TPoints!H43:FR43) -> -0.033158718 | BA3: =SLOPE(Pace!H3:FR3,TPoints!H3:FR3) -> 0.0051172557 | BB3: =SLOPE(Pace!H43:FR43,TPoints!H43:FR43) -> 0.0039330379 | BC3: =SLOPE(RSI!H3:FR3,TPoints!H3:FR3) -> -0.0029524293 | BD3: =SLOPE(RSI!H43:FR43,TPoints!H43:FR43) -> -0.00077944926 | BE3: =SLOPE(StepWidth!G3:FR3,TPoints!G3:FR3) -> -1.8888534 | BF3: =SLOPE(StepWidth!G43:FR43,TPoints!G43:FR43) -> -2.9011066 | BG3: =SLOPE(Distance!H3:FR3,TPoints!H3:FR3) -> 0.014513489 | BH3: =SLOPE(Distance!H43:FR43,TPoints!H43:FR43) -> -0.009033545 | BI3: =100*(MAX(TFlight!G3:FR3)-MIN(TFlight!G3:FR3))/MAX(TFlight!G3:FR3) -> 58.695652 | BJ3: =100*(MAX(TFlight!G43:FR43)-MIN(TFlight!G43:FR43))/MAX(TFlight!G43:FR43) -> 68.235294 | BK3: =100*(MAX(TContact!H3:FR3)-MIN(TContact!H3:FR3))/MAX(TContact!H3:FR3) -> 30.718954 | BL3: =100*(MAX(TContact!H43:FR43)-MIN(TContact!H43:FR43))/MAX(TContact!H43:FR43) -> 19.354839 | BM3: =100*(MAX(Elevation!G3:FR3)-MIN(Elevation!G3:FR3))/MAX(Elevation!G3:FR3) -> 82.795699 | BN3: =100*(MAX(Elevation!G43:FR43)-MIN(Elevation!G43:FR43))/MAX(Elevation!G43:FR43) -> 88.571429 | BO3: =100*(MAX(Power!H3:FR3)-MIN(Power!H3:FR3))/MAX(Power!H3:FR3) -> 73.617815 | BP3: =100*(MAX(Power!H43:FR43)-MIN(Power!H43:FR43))/MAX(Power!H43:FR43) -> 77.594258 | BQ3: =100*(MAX(Pace!H3:FR3)-MIN(Pace!H3:FR3))/MAX(Pace!H3:FR3) -> 22.957198 | BR3: =100*(MAX(Pace!H43:FR43)-MIN(Pace!H43:FR43))/MAX(Pace!H43:FR43) -> 20.909091 | BS3: =100*(MAX(RSI!H3:FR3)-MIN(RSI!H3:FR3))/MAX(RSI!H3:FR3) -> 86.331399 | BT3: =100*(MAX(RSI!H43:FR43)-MIN(RSI!H43:FR43))/MAX(RSI!H43:FR43) -> 90.33557 | BU3: =100*(MAX(StepWidth!G3:FR3)-MIN(StepWidth!G3:FR3))/MAX(StepWidth!G3:FR3) -> 67.538708 | BV3: =100*(MAX(StepWidth!G43:FR43)-MIN(StepWidth!G43:FR43))/MAX(StepWidth!G43:FR43) -> 47.376177 | BW3: =100*(MAX(Distance!H3:FR3)-MIN(Distance!H3:FR3))/MAX(Distance!H3:FR3) -> 100 | BX3: =100*(MAX(Distance!H43:FR43)-MIN(Distance!H43:FR43))/MAX(Distance!H43:FR43) -> 100
A4: 3 | B4: o3 | C4: J | D4: F | E4: 67 | F4: 67 | G4: 156 | H4: 156 | I4: 5.8 | J4: -5.8 | K4: 22.9 | L4: 20.8 | M4: 43.8 | N4: 22.9 | O4: 0.441 | P4: 0.41 | Q4: 23.8 | R4: 20.6 | S4: 105 | T4: 148 | U4: 0.27706667 | V4: 0.16422973 | W4: 0.29490385 | X4: 0.244 | Y4: 9.5580952 | Z4: 3.3581081 | AA4: 13.118771 | AB4: 6.6882934 | AC4: 1.7594164 | AD4: 2.4524987 | AE4: 0.32950798 | AF4: 0.13937434 | AG4: 9.2961538 | AH4: 4.2367347 | AI4: 5.8153846 | AJ4: 5.4054422 | AK4: 732.44571 | AL4: 315.01757 | AM4: 11.384442 | AN4: 3.9984232 | AO4: 59.762 | AP4: 60.174 | AQ4: 0.5691619 | AR4: 0.40658108 | AS4: =SLOPE(TFlight!G4:FR4,TPoints!G4:FR4) -> -0.0013306825 | AT4: =SLOPE(TFlight!G44:FR44,TPoints!G44:FR44) -> 0.0002711417 | AU4: =SLOPE(TContact!H4:FR4,TPoints!H4:FR4) -> -0.00022116082 | AV4: =SLOPE(TContact!H44:FR44,TPoints!H44:FR44) -> 7.5728396e-06 | AW4: =SLOPE(Elevation!G4:FR4,TPoints!G4:FR4) -> -0.084553303 | AX4: =SLOPE(Elevation!G44:FR44,TPoints!G44:FR44) -> 0.011937827 | AY4: =SLOPE(Power!H4:FR4,TPoints!H4:FR4) -> -0.088587874 | AZ4: =SLOPE(Power!H44:FR44,TPoints!H44:FR44) -> 0.015670324 | BA4: =SLOPE(Pace!H4:FR4,TPoints!H4:FR4) -> 0.0045518142 | BB4: =SLOPE(Pace!H44:FR44,TPoints!H44:FR44) -> -0.0015395972 | BC4: =SLOPE(RSI!H4:FR4,TPoints!H4:FR4) -> -0.0028536843 | BD4: =SLOPE(RSI!H44:FR44,TPoints!H44:FR44) -> 0.00049563862 | BE4: =SLOPE(StepWidth!G4:FR4,TPoints!G4:FR4) -> 3.2431868 | BF4: =SLOPE(StepWidth!G44:FR44,TPoints!G44:FR44) -> 0.18613512 | BG4: =SLOPE(Distance!H4:FR4,TPoints!H4:FR4) -> -0.031273173 | BH4: =SLOPE(Distance!H44:FR44,TPoints!H44:FR44) -> 0.015125209 | BI4: =100*(MAX(TFlight!G4:FR4)-MIN(TFlight!G4:FR4))/MAX(TFlight!G4:FR4) -> 58.181818 | BJ4: =100*(MAX(TFlight!G44:FR44)-MIN(TFlight!G44:FR44))/MAX(TFlight!G44:FR44) -> 51.304348 | BK4: =100*(MAX(TContact!H4:FR4)-MIN(TContact!H4:FR4))/MAX(TContact!H4:FR4) -> 65.363128 | BL4: =100*(MAX(TContact!H44:FR44)-MIN(TContact!H44:FR44))/MAX(TContact!H44:FR44) -> 24.647887 | BM4: =100*(MAX(Elevation!G4:FR4)-MIN(Elevation!G4:FR4))/MAX(Elevation!G4:FR4) -> 82.706767 | BN4: =100*(MAX(Elevation!G44:FR44)-MIN(Elevation!G44:FR44))/MAX(Elevation!G44:FR44) -> 76.923077 | BO4: =100*(MAX(Power!H4:FR4)-MIN(Power!H4:FR4))/MAX(Power!H4:FR4) -> 73.815731 | BP4: =100*(MAX(Power!H44:FR44)-MIN(Power!H44:FR44))/MAX(Power!H44:FR44) -> 63.795774 | BQ4: =100*(MAX(Pace!H4:FR4)-MIN(Pace!H4:FR4))/MAX(Pace!H4:FR4) -> 54.618474 | BR4: =100*(MAX(Pace!H44:FR44)-MIN(Pace!H44:FR44))/MAX(Pace!H44:FR44) -> 23.75 | BS4: =100*(MAX(RSI!H4:FR4)-MIN(RSI!H4:FR4))/MAX(RSI!H4:FR4) -> 87.306202 | BT4: =100*(MAX(RSI!H44:FR44)-MIN(RSI!H44:FR44))/MAX(RSI!H44:FR44) -> 77.980035 | BU4: =100*(MAX(StepWidth!G4:FR4)-MIN(StepWidth!G4:FR4))/MAX(StepWidth!G4:FR4) -> 52.590314 | BV4: =100*(MAX(StepWidth!G44:FR44)-MIN(StepWidth!G44:FR44))/MAX(StepWidth!G44:FR44) -> 60.880881 | BW4: =100*(MAX(Distance!H4:FR4)-MIN(Distance!H4:FR4))/MAX(Distance!H4:FR4) -> 100 | BX4: =100*(MAX(Distance!H44:FR44)-MIN(Distance!H44:FR44))/MAX(Distance!H44:FR44) -> 100
A5: 4 | B5: o4 | C5: B | D5: F | E5: 63 | F5: 63 | G5: 151 | H5: 151 | I5: -6.3 | J5: -1.5 | K5: 24 | L5: 25 | M5: 25 | N5: 27.1 | O5: 0.352 | P5: 0.288 | Q5: 15.2 | R5: 10.2 | S5: 122 | T5: 140 | U5: 0.23113115 | V5: 0.11215714 | W5: 0.26495868 | X5: 0.31936691 | Y5: 6.707377 | Z5: 1.5578571 | AA5: 10.580177 | AB5: 3.6558787 | AC5: 2.0242633 | AD5: 2.3202023 | AE5: 0.25670932 | AF5: 0.049057882 | AG5: 6.1471074 | AH5: 8.0820144 | AI5: 14.550413 | AJ5: 8.7388489 | AK5: 447.20164 | AL5: 633.07429 | AM5: 6.9325309 | AN5: 2.984601 | AO5: 60.258 | AP5: 60.094 | AQ5: 0.49391803 | AR5: 0.42924286 | AS5: =SLOPE(TFlight!G5:FR5,TPoints!G5:FR5) -> -0.0010880268 | AT5: =SLOPE(TFlight!G45:FR45,TPoints!G45:FR45) -> -0.00026858917 | AU5: =SLOPE(TContact!H5:FR5,TPoints!H5:FR5) -> 0.00020250929 | AV5: =SLOPE(TContact!H45:FR45,TPoints!H45:FR45) -> 0.00043107786 | AW5: =SLOPE(Elevation!G5:FR5,TPoints!G5:FR5) -> -0.062688248 | AX5: =SLOPE(Elevation!G45:FR45,TPoints!G45:FR45) -> -0.0075719827 | AY5: =SLOPE(Power!H5:FR5,TPoints!H5:FR5) -> -0.073324366 | AZ5: =SLOPE(Power!H45:FR45,TPoints!H45:FR45) -> -0.01177754 | BA5: =SLOPE(Pace!H5:FR5,TPoints!H5:FR5) -> 0.0033908977 | BB5: =SLOPE(Pace!H45:FR45,TPoints!H45:FR45) -> -0.00096159125 | BC5: =SLOPE(RSI!H5:FR5,TPoints!H5:FR5) -> -0.0024366125 | BD5: =SLOPE(RSI!H45:FR45,TPoints!H45:FR45) -> -0.00029440403 | BE5: =SLOPE(StepWidth!G5:FR5,TPoints!G5:FR5) -> -0.5049609 | BF5: =SLOPE(StepWidth!G45:FR45,TPoints!G45:FR45) -> -0.71146441 | BG5: =SLOPE(Distance!H5:FR5,TPoints!H5:FR5) -> -0.0016277799 | BH5: =SLOPE(Distance!H45:FR45,TPoints!H45:FR45) -> 0.010562349 | BI5: =100*(MAX(TFlight!G5:FR5)-MIN(TFlight!G5:FR5))/MAX(TFlight!G5:FR5) -> 51.851852 | BJ5: =100*(MAX(TFlight!G45:FR45)-MIN(TFlight!G45:FR45))/MAX(TFlight!G45:FR45) -> 47.945205 | BK5: =100*(MAX(TContact!H5:FR5)-MIN(TContact!H5:FR5))/MAX(TContact!H5:FR5) -> 30.434783 | BL5: =100*(MAX(TContact!H45:FR45)-MIN(TContact!H45:FR45))/MAX(TContact!H45:FR45) -> 23.076923 | BM5: =100*(MAX(Elevation!G5:FR5)-MIN(Elevation!G5:FR5))/MAX(Elevation!G5:FR5) -> 76.744186 | BN5: =100*(MAX(Elevation!G45:FR45)-MIN(Elevation!G45:FR45))/MAX(Elevation!G45:FR45) -> 73.076923 | BO5: =100*(MAX(Power!H5:FR5)-MIN(Power!H5:FR5))/MAX(Power!H5:FR5) -> 68.315392 | BP5: =100*(MAX(Power!H45:FR45)-MIN(Power!H45:FR45))/MAX(Power!H45:FR45) -> 56.777251 | BQ5: =100*(MAX(Pace!H5:FR5)-MIN(Pace!H5:FR5))/MAX(Pace!H5:FR5) -> 26.804124 | BR5: =100*(MAX(Pace!H45:FR45)-MIN(Pace!H45:FR45))/MAX(Pace!H45:FR45) -> 10.964912 | BS5: =100*(MAX(RSI!H5:FR5)-MIN(RSI!H5:FR5))/MAX(RSI!H5:FR5) -> 81.36646 | BT5: =100*(MAX(RSI!H45:FR45)-MIN(RSI!H45:FR45))/MAX(RSI!H45:FR45) -> 77.6 | BU5: =100*(MAX(StepWidth!G5:FR5)-MIN(StepWidth!G5:FR5))/MAX(StepWidth!G5:FR5) -> 66.662015 | BV5: =100*(MAX(StepWidth!G45:FR45)-MIN(StepWidth!G45:FR45))/MAX(StepWidth!G45:FR45) -> 28.88525 | BW5: =100*(MAX(Distance!H5:FR5)-MIN(Distance!H5:FR5))/MAX(Distance!H5:FR5) -> 99.452045 | BX5: =100*(MAX(Distance!H45:FR45)-MIN(Distance!H45:FR45))/MAX(Distance!H45:FR45) -> 100
A6: 5 | B6: o5 | C6: J | D6: M | E6: 58 | F6: 58 | G6: 146 | H6: 146 | I6: 6.8 | J6: -17.2 | K6: 24 | L6: 26 | M6: 47.9 | N6: 29.2 | O6: 0.437 | P6: 0.435 | Q6: 23.4 | R6: 23.2 | S6: 104 | T6: 156 | U6: 0.29269231 | V6: 0.13394872 | W6: 0.28415534 | X6: 0.25207742 | Y6: 10.629808 | Z6: 2.2961538 | AA6: 14.446068 | AB6: 5.3022272 | AC6: 1.7386097 | AD6: 2.6264175 | AE6: 0.37799077 | AF6: 0.10604977 | AG6: 9.2563107 | AH6: 8.8464516 | AI6: 10.61165 | AJ6: 4.2819355 | AK6: 623.32019 | AL6: 555.73782 | AM6: 9.1813938 | AN6: 4.8235315 | AO6: 59.708 | AP6: 59.968 | AQ6: 0.57411538 | AR6: 0.38441026 | AS6: =SLOPE(TFlight!G6:FR6,TPoints!G6:FR6) -> -0.0012340379 | AT6: =SLOPE(TFlight!G46:FR46,TPoints!G46:FR46) -> -0.00085852537 | AU6: =SLOPE(TContact!H6:FR6,TPoints!H6:FR6) -> 0.00033848779 | AV6: =SLOPE(TContact!H46:FR46,TPoints!H46:FR46) -> 0.00073622022 | AW6: =SLOPE(Elevation!G6:FR6,TPoints!G6:FR6) -> -0.087679877 | AX6: =SLOPE(Elevation!G46:FR46,TPoints!G46:FR46) -> -0.028221347 | AY6: =SLOPE(Power!H6:FR6,TPoints!H6:FR6) -> -0.101877 | AZ6: =SLOPE(Power!H46:FR46,TPoints!H46:FR46) -> -0.056152444 | BA6: =SLOPE(Pace!H6:FR6,TPoints!H6:FR6) -> 0.0027668923 | BB6: =SLOPE(Pace!H46:FR46,TPoints!H46:FR46) -> 0.00060481403 | BC6: =SLOPE(RSI!H6:FR6,TPoints!H6:FR6) -> -0.003642162 | BD6: =SLOPE(RSI!H46:FR46,TPoints!H46:FR46) -> -0.0018243158 | BE6: =SLOPE(StepWidth!G6:FR6,TPoints!G6:FR6) -> 1.0193617 | BF6: =SLOPE(StepWidth!G46:FR46,TPoints!G46:FR46) -> 1.0289935 | BG6: =SLOPE(Distance!H6:FR6,TPoints!H6:FR6) -> -0.05657095 | BH6: =SLOPE(Distance!H46:FR46,TPoints!H46:FR46) -> -0.023902045 | BI6: =100*(MAX(TFlight!G6:FR6)-MIN(TFlight!G6:FR6))/MAX(TFlight!G6:FR6) -> 46.511628 | BJ6: =100*(MAX(TFlight!G46:FR46)-MIN(TFlight!G46:FR46))/MAX(TFlight!G46:FR46) -> 93.548387 | BK6: =100*(MAX(TContact!H6:FR6)-MIN(TContact!H6:FR6))/MAX(TContact!H6:FR6) -> 32.58427 | BL6: =100*(MAX(TContact!H46:FR46)-MIN(TContact!H46:FR46))/MAX(TContact!H46:FR46) -> 98.397436 | BM6: =100*(MAX(Elevation!G6:FR6)-MIN(Elevation!G6:FR6))/MAX(Elevation!G6:FR6) -> 71.034483 | BN6: =100*(MAX(Elevation!G46:FR46)-MIN(Elevation!G46:FR46))/MAX(Elevation!G46:FR46) -> 100 | BO6: =100*(MAX(Power!H6:FR6)-MIN(Power!H6:FR6))/MAX(Power!H6:FR6) -> 63.398195 | BP6: =100*(MAX(Power!H46:FR46)-MIN(Power!H46:FR46))/MAX(Power!H46:FR46) -> 99.328817 | BQ6: =100*(MAX(Pace!H6:FR6)-MIN(Pace!H6:FR6))/MAX(Pace!H6:FR6) -> 27.743902 | BR6: =100*(MAX(Pace!H46:FR46)-MIN(Pace!H46:FR46))/MAX(Pace!H46:FR46) -> 80.38674 | BS6: =100*(MAX(RSI!H6:FR6)-MIN(RSI!H6:FR6))/MAX(RSI!H6:FR6) -> 75.522098 | BT6: =100*(MAX(RSI!H46:FR46)-MIN(RSI!H46:FR46))/MAX(RSI!H46:FR46) -> 100 | BU6: =100*(MAX(StepWidth!G6:FR6)-MIN(StepWidth!G6:FR6))/MAX(StepWidth!G6:FR6) -> 59.559819 | BV6: =100*(MAX(StepWidth!G46:FR46)-MIN(StepWidth!G46:FR46))/MAX(StepWidth!G46:FR46) -> 99.703184 | BW6: =100*(MAX(Distance!H6:FR6)-MIN(Distance!H6:FR6))/MAX(Distance!H6:FR6) -> 98.367612 | BX6: =100*(MAX(Distance!H46:FR46)-MIN(Distance!H46:FR46))/MAX(Distance!H46:FR46) -> 97.767857
A7: 6 | B7: o6 | C7: B | D7: M | E7: 59 | F7: 59 | G7: 149 | H7: 149 | I7: 2 | J7: 0 | K7: 24 | L7: 27.1 | M7: 22.9 | N7: 31.3 | O7: 0.324 | P7: 0.43 | Q7: 12.9 | R7: 22.7 | S7: 144 | T7: 130 | U7: 0.17319444 | V7: 0.18507692 | W7: 0.24577622 | X7: 0.2795814 | Y7: 3.7819444 | Z7: 4.3015385 | AA7: 7.3377124 | AB7: 7.5670547 | AC7: 2.4222812 | AD7: 2.1537381 | AE7: 0.16155303 | AF7: 0.15844546 | AG7: 8.3573427 | AH7: 9.596124 | AI7: 6.7104895 | AJ7: 15.573643 | AK7: 461.00833 | AL7: 774.57154 | AM7: 5.7043799 | AN7: 6.374987 | AO7: 60.086 | AP7: 60.126 | AQ7: 0.41726389 | AR7: 0.46250769 | AS7: =SLOPE(TFlight!G7:FR7,TPoints!G7:FR7) -> -0.00045430103 | AT7: =SLOPE(TFlight!G47:FR47,TPoints!G47:FR47) -> -0.0010032621 | AU7: =SLOPE(TContact!H7:FR7,TPoints!H7:FR7) -> -0.00072134029 | AV7: =SLOPE(TContact!H47:FR47,TPoints!H47:FR47) -> 0.00062684576 | AW7: =SLOPE(Elevation!G7:FR7,TPoints!G7:FR7) -> -0.018629115 | AX7: =SLOPE(Elevation!G47:FR47,TPoints!G47:FR47) -> -0.046591274 | AY7: =SLOPE(Power!H7:FR7,TPoints!H7:FR7) -> -0.024643129 | AZ7: =SLOPE(Power!H47:FR47,TPoints!H47:FR47) -> -0.068407255 | BA7: =SLOPE(Pace!H7:FR7,TPoints!H7:FR7) -> 0.0045972866 | BB7: =SLOPE(Pace!H47:FR47,TPoints!H47:FR47) -> 0.0020151427 | BC7: =SLOPE(RSI!H7:FR7,TPoints!H7:FR7) -> -0.00067268364 | BD7: =SLOPE(RSI!H47:FR47,TPoints!H47:FR47) -> -0.0021842505 | BE7: =SLOPE(StepWidth!G7:FR7,TPoints!G7:FR7) -> -0.8807157 | BF7: =SLOPE(StepWidth!G47:FR47,TPoints!G47:FR47) -> 6.5505812 | BG7: =SLOPE(Distance!H7:FR7,TPoints!H7:FR7) -> -0.024558802 | BH7: =SLOPE(Distance!H47:FR47,TPoints!H47:FR47) -> -0.033193772 | BI7: =100*(MAX(TFlight!G7:FR7)-MIN(TFlight!G7:FR7))/MAX(TFlight!G7:FR7) -> 54.411765 | BJ7: =100*(MAX(TFlight!G47:FR47)-MIN(TFlight!G47:FR47))/MAX(TFlight!G47:FR47) -> 52.713178 | BK7: =100*(MAX(TContact!H7:FR7)-MIN(TContact!H7:FR7))/MAX(TContact!H7:FR7) -> 84.163701 | BL7: =100*(MAX(TContact!H47:FR47)-MIN(TContact!H47:FR47))/MAX(TContact!H47:FR47) -> 37.572254 | BM7: =100*(MAX(Elevation!G7:FR7)-MIN(Elevation!G7:FR7))/MAX(Elevation!G7:FR7) -> 79.120879 | BN7: =100*(MAX(Elevation!G47:FR47)-MIN(Elevation!G47:FR47))/MAX(Elevation!G47:FR47) -> 78.04878 | BO7: =100*(MAX(Power!H7:FR7)-MIN(Power!H7:FR7))/MAX(Power!H7:FR7) -> 69.262168 | BP7: =100*(MAX(Power!H47:FR47)-MIN(Power!H47:FR47))/MAX(Power!H47:FR47) -> 69.993976 | BQ7: =100*(MAX(Pace!H7:FR7)-MIN(Pace!H7:FR7))/MAX(Pace!H7:FR7) -> 74.277017 | BR7: =100*(MAX(Pace!H47:FR47)-MIN(Pace!H47:FR47))/MAX(Pace!H47:FR47) -> 18.4 | BS7: =100*(MAX(RSI!H7:FR7)-MIN(RSI!H7:FR7))/MAX(RSI!H7:FR7) -> 90.583822 | BT7: =100*(MAX(RSI!H47:FR47)-MIN(RSI!H47:FR47))/MAX(RSI!H47:FR47) -> 85.535035 | BU7: =100*(MAX(StepWidth!G7:FR7)-MIN(StepWidth!G7:FR7))/MAX(StepWidth!G7:FR7) -> 68.182347 | BV7: =100*(MAX(StepWidth!G47:FR47)-MIN(StepWidth!G47:FR47))/MAX(StepWidth!G47:FR47) -> 100 | BW7: =100*(MAX(Distance!H7:FR7)-MIN(Distance!H7:FR7))/MAX(Distance!H7:FR7) -> 96.246479 | BX7: =100*(MAX(Distance!H47:FR47)-MIN(Distance!H47:FR47))/MAX(Distance!H47:FR47) -> 97.38735
A8: 7 | B8: o7 | C8: B | D8: M | E8: 50 | F8: 50 | G8: 139 | H8: 139 | I8: -8.3 | J8: -11 | K8: 24 | L8: 26 | M8: 28.1 | N8: 31.3 | O8: 0.343 | P8: 0.507 | Q8: 14.4 | R8: 31.5 | S8: 125 | T8: 168 | U8: 0.226608 | V8: 0.13090476 | W8: 0.2548871 | X8: 0.22851497 | Y8: 6.5736 | Z8: 2.1452381 | AA8: 10.796044 | AB8: 5.0589975 | AC8: 2.1053886 | AD8: 2.7908251 | AE8: 0.27186773 | AF8: 0.097337146 | AG8: 19.176613 | AH8: 4.2215569 | AI8: 18.567742 | AJ8: 5.8532934 | AK8: 568.2856 | AL8: 400.67262 | AM8: 9.7233426 | AN8: 3.868963 | AO8: 59.932 | AP8: 60.154 | AQ8: 0.479456 | AR8: 0.35805952 | AS8: =SLOPE(TFlight!G8:FR8,TPoints!G8:FR8) -> -0.00076993923 | AT8: =SLOPE(TFlight!G48:FR48,TPoints!G48:FR48) -> -0.00051646271 | AU8: =SLOPE(TContact!H8:FR8,TPoints!H8:FR8) -> 0.0010976802 | AV8: =SLOPE(TContact!H48:FR48,TPoints!H48:FR48) -> 0.0010295858 | AW8: =SLOPE(Elevation!G8:FR8,TPoints!G8:FR8) -> -0.037853796 | AX8: =SLOPE(Elevation!G48:FR48,TPoints!G48:FR48) -> -0.017288634 | AY8: =SLOPE(Power!H8:FR8,TPoints!H8:FR8) -> -0.065554966 | AZ8: =SLOPE(Power!H48:FR48,TPoints!H48:FR48) -> -0.037762011 | BA8: =SLOPE(Pace!H8:FR8,TPoints!H8:FR8) -> 0.00050749082 | BB8: =SLOPE(Pace!H48:FR48,TPoints!H48:FR48) -> -0.0039899954 | BC8: =SLOPE(RSI!H8:FR8,TPoints!H8:FR8) -> -0.0023044388 | BD8: =SLOPE(RSI!H48:FR48,TPoints!H48:FR48) -> -0.001291275 | BE8: =SLOPE(StepWidth!G8:FR8,TPoints!G8:FR8) -> 4.6707936 | BF8: =SLOPE(StepWidth!G48:FR48,TPoints!G48:FR48) -> -1.0413755 | BG8: =SLOPE(Distance!H8:FR8,TPoints!H8:FR8) -> 0.03876446 | BH8: =SLOPE(Distance!H48:FR48,TPoints!H48:FR48) -> -0.018800585 | BI8: =100*(MAX(TFlight!G8:FR8)-MIN(TFlight!G8:FR8))/MAX(TFlight!G8:FR8) -> 90.419162 | BJ8: =100*(MAX(TFlight!G48:FR48)-MIN(TFlight!G48:FR48))/MAX(TFlight!G48:FR48) -> 53.932584 | BK8: =100*(MAX(TContact!H8:FR8)-MIN(TContact!H8:FR8))/MAX(TContact!H8:FR8) -> 77.230047 | BL8: =100*(MAX(TContact!H48:FR48)-MIN(TContact!H48:FR48))/MAX(TContact!H48:FR48) -> 45.517241 | BM8: =100*(MAX(Elevation!G8:FR8)-MIN(Elevation!G8:FR8))/MAX(Elevation!G8:FR8) -> 99.270073 | BN8: =100*(MAX(Elevation!G48:FR48)-MIN(Elevation!G48:FR48))/MAX(Elevation!G48:FR48) -> 79.487179 | BO8: =100*(MAX(Power!H8:FR8)-MIN(Power!H8:FR8))/MAX(Power!H8:FR8) -> 95.752843 | BP8: =100*(MAX(Power!H48:FR48)-MIN(Power!H48:FR48))/MAX(Power!H48:FR48) -> 71.288387 | BQ8: =100*(MAX(Pace!H8:FR8)-MIN(Pace!H8:FR8))/MAX(Pace!H8:FR8) -> 70.676692 | BR8: =100*(MAX(Pace!H48:FR48)-MIN(Pace!H48:FR48))/MAX(Pace!H48:FR48) -> 25.837321 | BS8: =100*(MAX(RSI!H8:FR8)-MIN(RSI!H8:FR8))/MAX(RSI!H8:FR8) -> 99.490332 | BT8: =100*(MAX(RSI!H48:FR48)-MIN(RSI!H48:FR48))/MAX(RSI!H48:FR48) -> 87.138787 | BU8: =100*(MAX(StepWidth!G8:FR8)-MIN(StepWidth!G8:FR8))/MAX(StepWidth!G8:FR8) -> 76.742526 | BV8: =100*(MAX(StepWidth!G48:FR48)-MIN(StepWidth!G48:FR48))/MAX(StepWidth!G48:FR48) -> 74.546781 | BW8: =100*(MAX(Distance!H8:FR8)-MIN(Distance!H8:FR8))/MAX(Distance!H8:FR8) -> 98.509063 | BX8: =100*(MAX(Distance!H48:FR48)-MIN(Distance!H48:FR48))/MAX(Distance!H48:FR48) -> 95.86112
A9: 8 | B9: o8 | C9: B | D9: F | E9: 62 | F9: 62 | G9: 150 | H9: 150 | I9: 3.6 | J9: -11.9 | K9: 25 | L9: 27.1 | M9: 27.1 | N9: 28.1 | O9: 0.356 | P9: 0.309 | Q9: 15.5 | R9: 11.7 | S9: 167 | T9: 118 | U9: 0.14863473 | V9: 0.176 | W9: 0.21239759 | X9: 0.33547009 | Y9: 2.8041916 | Z9: 3.9127119 | AA9: 6.2489169 | AB9: 6.5738591 | AC9: 2.782822 | AD9: 1.9579041 | AE9: 0.1358733 | AF9: 0.11958102 | AG9: 5.2439759 | AH9: 2.8803419 | AI9: 10.383735 | AJ9: 8.4598291 | AK9: 533.3485 | AL9: 595.69746 | AM9: 4.9613023 | AN9: 5.0255933 | AO9: 60.08 | AP9: 60.018 | AQ9: 0.35976048 | AR9: 0.50862712 | AS9: =SLOPE(TFlight!G9:FR9,TPoints!G9:FR9) -> -0.00067424035 | AT9: =SLOPE(TFlight!G49:FR49,TPoints!G49:FR49) -> -0.0016184039 | AU9: =SLOPE(TContact!H9:FR9,TPoints!H9:FR9) -> 0.00050254337 | AV9: =SLOPE(TContact!H49:FR49,TPoints!H49:FR49) -> 0.0012081138 | AW9: =SLOPE(Elevation!G9:FR9,TPoints!G9:FR9) -> -0.025847364 | AX9: =SLOPE(Elevation!G49:FR49,TPoints!G49:FR49) -> -0.069430856 | AY9: =SLOPE(Power!H9:FR9,TPoints!H9:FR9) -> -0.048890743 | AZ9: =SLOPE(Power!H49:FR49,TPoints!H49:FR49) -> -0.089817615 | BA9: =SLOPE(Pace!H9:FR9,TPoints!H9:FR9) -> 0.001452834 | BB9: =SLOPE(Pace!H49:FR49,TPoints!H49:FR49) -> 0.0016651349 | BC9: =SLOPE(RSI!H9:FR9,TPoints!H9:FR9) -> -0.0016059533 | BD9: =SLOPE(RSI!H49:FR49,TPoints!H49:FR49) -> -0.0025605763 | BE9: =SLOPE(StepWidth!G9:FR9,TPoints!G9:FR9) -> 0.68330806 | BF9: =SLOPE(StepWidth!G49:FR49,TPoints!G49:FR49) -> -2.2070478 | BG9: =SLOPE(Distance!H9:FR9,TPoints!H9:FR9) -> 0.0049770575 | BH9: =SLOPE(Distance!H49:FR49,TPoints!H49:FR49) -> -0.039782656 | BI9: =100*(MAX(TFlight!G9:FR9)-MIN(TFlight!G9:FR9))/MAX(TFlight!G9:FR9) -> 66.972477 | BJ9: =100*(MAX(TFlight!G49:FR49)-MIN(TFlight!G49:FR49))/MAX(TFlight!G49:FR49) -> 56 | BK9: =100*(MAX(TContact!H9:FR9)-MIN(TContact!H9:FR9))/MAX(TContact!H9:FR9) -> 38.888889 | BL9: =100*(MAX(TContact!H49:FR49)-MIN(TContact!H49:FR49))/MAX(TContact!H49:FR49) -> 29.591837 | BM9: =100*(MAX(Elevation!G9:FR9)-MIN(Elevation!G9:FR9))/MAX(Elevation!G9:FR9) -> 89.655172 | BN9: =100*(MAX(Elevation!G49:FR49)-MIN(Elevation!G49:FR49))/MAX(Elevation!G49:FR49) -> 80.519481 | BO9: =100*(MAX(Power!H9:FR9)-MIN(Power!H9:FR9))/MAX(Power!H9:FR9) -> 79.607843 | BP9: =100*(MAX(Power!H49:FR49)-MIN(Power!H49:FR49))/MAX(Power!H49:FR49) -> 69.137867 | BQ9: =100*(MAX(Pace!H9:FR9)-MIN(Pace!H9:FR9))/MAX(Pace!H9:FR9) -> 32.579186 | BR9: =100*(MAX(Pace!H49:FR49)-MIN(Pace!H49:FR49))/MAX(Pace!H49:FR49) -> 17.375887 | BS9: =100*(MAX(RSI!H9:FR9)-MIN(RSI!H9:FR9))/MAX(RSI!H9:FR9) -> 91.578947 | BT9: =100*(MAX(RSI!H49:FR49)-MIN(RSI!H49:FR49))/MAX(RSI!H49:FR49) -> 84.992049 | BU9: =100*(MAX(StepWidth!G9:FR9)-MIN(StepWidth!G9:FR9))/MAX(StepWidth!G9:FR9) -> 57.268433 | BV9: =100*(MAX(StepWidth!G49:FR49)-MIN(StepWidth!G49:FR49))/MAX(StepWidth!G49:FR49) -> 54.022583 | BW9: =100*(MAX(Distance!H9:FR9)-MIN(Distance!H9:FR9))/MAX(Distance!H9:FR9) -> 100 | BX9: =100*(MAX(Distance!H49:FR49)-MIN(Distance!H49:FR49))/MAX(Distance!H49:FR49) -> 96.550955
A10: 9 | B10: o9 | C10: B | D10: M | E10: 73 | F10: 73 | G10: 156 | H10: 156 | I10: 4.2 | J10: 0 | K10: 24 | L10: 27.1 | M10: 30.2 | N10: 28.1 | O10: 0.406 | P10: 0.362 | Q10: 20.2 | R10: 16.1 | S10: 147 | T10: 117 | U10: 0.11587755 | V10: 0.27639316 | W10: 0.294 | X10: 0.24046552 | Y10: 1.7530612 | Z10: 9.4350427 | AA10: 3.9713112 | AB10: 14.464824 | AC10: 2.4788886 | AD10: 1.9356884 | AE10: 0.060800359 | AF10: 0.39792347 | AG10: 9.559589 | AH10: 12.437931 | AI10: 13.228082 | AJ10: 12.140517 | AK10: 829.02313 | AL10: 472.19573 | AM10: 4.1755014 | AN10: 6.9601398 | AO10: 59.958 | AP10: 60.232 | AQ10: 0.40787755 | AR10: 0.51480342 | AS10: =SLOPE(TFlight!G10:FR10,TPoints!G10:FR10) -> -0.00092493018 | AT10: =SLOPE(TFlight!G50:FR50,TPoints!G50:FR50) -> -0.00064942582 | AU10: =SLOPE(TContact!H10:FR10,TPoints!H10:FR10) -> 2.9047345e-05 | AV10: =SLOPE(TContact!H50:FR50,TPoints!H50:FR50) -> 0.00038700536 | AW10: =SLOPE(Elevation!G10:FR10,TPoints!G10:FR10) -> -0.030113658 | AX10: =SLOPE(Elevation!G50:FR50,TPoints!G50:FR50) -> -0.044805657 | AY10: =SLOPE(Power!H10:FR10,TPoints!H10:FR10) -> -0.039547261 | AZ10: =SLOPE(Power!H50:FR50,TPoints!H50:FR50) -> -0.070407269 | BA10: =SLOPE(Pace!H10:FR10,TPoints!H10:FR10) -> 0.0052935873 | BB10: =SLOPE(Pace!H50:FR50,TPoints!H50:FR50) -> 0.0012282218 | BC10: =SLOPE(RSI!H10:FR10,TPoints!H10:FR10) -> -0.00093040311 | BD10: =SLOPE(RSI!H50:FR50,TPoints!H50:FR50) -> -0.0027110333 | BE10: =SLOPE(StepWidth!G10:FR10,TPoints!G10:FR10) -> -4.5605151 | BF10: =SLOPE(StepWidth!G50:FR50,TPoints!G50:FR50) -> 0.1020417 | BG10: =SLOPE(Distance!H10:FR10,TPoints!H10:FR10) -> 0.022242472 | BH10: =SLOPE(Distance!H50:FR50,TPoints!H50:FR50) -> 0.017346054 | BI10: =100*(MAX(TFlight!G10:FR10)-MIN(TFlight!G10:FR10))/MAX(TFlight!G10:FR10) -> 84.126984 | BJ10: =100*(MAX(TFlight!G50:FR50)-MIN(TFlight!G50:FR50))/MAX(TFlight!G50:FR50) -> 37.790698 | BK10: =100*(MAX(TContact!H10:FR10)-MIN(TContact!H10:FR10))/MAX(TContact!H10:FR10) -> 70.605187 | BL10: =100*(MAX(TContact!H50:FR50)-MIN(TContact!H50:FR50))/MAX(TContact!H50:FR50) -> 26.428571 | BM10: =100*(MAX(Elevation!G10:FR10)-MIN(Elevation!G10:FR10))/MAX(Elevation!G10:FR10) -> 97.435897 | BN10: =100*(MAX(Elevation!G50:FR50)-MIN(Elevation!G50:FR50))/MAX(Elevation!G50:FR50) -> 61.37931 | BO10: =100*(MAX(Power!H10:FR10)-MIN(Power!H10:FR10))/MAX(Power!H10:FR10) -> 90.904018 | BP10: =100*(MAX(Power!H50:FR50)-MIN(Power!H50:FR50))/MAX(Power!H50:FR50) -> 55.336198 | BQ10: =100*(MAX(Pace!H10:FR10)-MIN(Pace!H10:FR10))/MAX(Pace!H10:FR10) -> 55.858311 | BR10: =100*(MAX(Pace!H50:FR50)-MIN(Pace!H50:FR50))/MAX(Pace!H50:FR50) -> 18.085106 | BS10: =100*(MAX(RSI!H10:FR10)-MIN(RSI!H10:FR10))/MAX(RSI!H10:FR10) -> 98.898988 | BT10: =100*(MAX(RSI!H50:FR50)-MIN(RSI!H50:FR50))/MAX(RSI!H50:FR50) -> 67.057569 | BU10: =100*(MAX(StepWidth!G10:FR10)-MIN(StepWidth!G10:FR10))/MAX(StepWidth!G10:FR10) -> 63.315195 | BV10: =100*(MAX(StepWidth!G50:FR50)-MIN(StepWidth!G50:FR50))/MAX(StepWidth!G50:FR50) -> 100 | BW10: =100*(MAX(Distance!H10:FR10)-MIN(Distance!H10:FR10))/MAX(Distance!H10:FR10) -> 98.611956 | BX10: =100*(MAX(Distance!H50:FR50)-MIN(Distance!H50:FR50))/MAX(Distance!H50:FR50) -> 100
A11: 10 | B11: o10 | C11: J | D11: F | E11: 67 | F11: 67 | G11: 158 | H11: 158 | I11: 6.7 | J11: -4.7 | K11: 26 | L11: 27.1 | M11: 26 | N11: 34.4 | O11: 0.461 | P11: 0.36 | Q11: 26.1 | R11: 15.9 | S11: 114 | T11: 121 | U11: 0.22185965 | V11: 0.15449587 | W11: 0.30663717 | X11: 0.3439 | Y11: 6.1342105 | Z11: 3.0330579 | AA11: 9.3209724 | AB11: 5.4565399 | AC11: 1.89643 | AD11: 2.0128456 | AE11: 0.20393189 | AF11: 0.089175428 | AG11: 10.309735 | AH11: 4.005 | AI11: 3.9964602 | AJ11: 6.8875 | AK11: 699.25789 | AL11: 662.96281 | AM11: 7.3488496 | AN11: 4.0728965 | AO11: 59.942 | AP11: 59.962 | AQ11: 0.52580702 | AR11: 0.49555372 | AS11: =SLOPE(TFlight!G11:FR11,TPoints!G11:FR11) -> -0.00061808464 | AT11: =SLOPE(TFlight!G51:FR51,TPoints!G51:FR51) -> -0.0013162418 | AU11: =SLOPE(TContact!H11:FR11,TPoints!H11:FR11) -> 0.0001870422 | AV11: =SLOPE(TContact!H51:FR51,TPoints!H51:FR51) -> 0.00044264205 | AW11: =SLOPE(Elevation!G11:FR11,TPoints!G11:FR11) -> -0.036761698 | AX11: =SLOPE(Elevation!G51:FR51,TPoints!G51:FR51) -> -0.0485035 | AY11: =SLOPE(Power!H11:FR11,TPoints!H11:FR11) -> -0.040952864 | AZ11: =SLOPE(Power!H51:FR51,TPoints!H51:FR51) -> -0.061451937 | BA11: =SLOPE(Pace!H11:FR11,TPoints!H11:FR11) -> 0.0013749525 | BB11: =SLOPE(Pace!H51:FR51,TPoints!H51:FR51) -> 0.0036325421 | BC11: =SLOPE(RSI!H11:FR11,TPoints!H11:FR11) -> -0.0013891652 | BD11: =SLOPE(RSI!H51:FR51,TPoints!H51:FR51) -> -0.0015129188 | BE11: =SLOPE(StepWidth!G11:FR11,TPoints!G11:FR11) -> 0.55922474 | BF11: =SLOPE(StepWidth!G51:FR51,TPoints!G51:FR51) -> -3.9434148 | BG11: =SLOPE(Distance!H11:FR11,TPoints!H11:FR11) -> 0.021503282 | BH11: =SLOPE(Distance!H51:FR51,TPoints!H51:FR51) -> -0.021679554 | BI11: =100*(MAX(TFlight!G11:FR11)-MIN(TFlight!G11:FR11))/MAX(TFlight!G11:FR11) -> 48.101266 | BJ11: =100*(MAX(TFlight!G51:FR51)-MIN(TFlight!G51:FR51))/MAX(TFlight!G51:FR51) -> 78.095238 | BK11: =100*(MAX(TContact!H11:FR11)-MIN(TContact!H11:FR11))/MAX(TContact!H11:FR11) -> 36.787565 | BL11: =100*(MAX(TContact!H51:FR51)-MIN(TContact!H51:FR51))/MAX(TContact!H51:FR51) -> 28.436019 | BM11: =100*(MAX(Elevation!G11:FR11)-MIN(Elevation!G11:FR11))/MAX(Elevation!G11:FR11) -> 72.95082 | BN11: =100*(MAX(Elevation!G51:FR51)-MIN(Elevation!G51:FR51))/MAX(Elevation!G51:FR51) -> 94.444444 | BO11: =100*(MAX(Power!H11:FR11)-MIN(Power!H11:FR11))/MAX(Power!H11:FR11) -> 67.779376 | BP11: =100*(MAX(Power!H51:FR51)-MIN(Power!H51:FR51))/MAX(Power!H51:FR51) -> 85.17747 | BQ11: =100*(MAX(Pace!H11:FR11)-MIN(Pace!H11:FR11))/MAX(Pace!H11:FR11) -> 15.789474 | BR11: =100*(MAX(Pace!H51:FR51)-MIN(Pace!H51:FR51))/MAX(Pace!H51:FR51) -> 25.724638 | BS11: =100*(MAX(RSI!H11:FR11)-MIN(RSI!H11:FR11))/MAX(RSI!H11:FR11) -> 82.901554 | BT11: =100*(MAX(RSI!H51:FR51)-MIN(RSI!H51:FR51))/MAX(RSI!H51:FR51) -> 95.177045 | BU11: =100*(MAX(StepWidth!G11:FR11)-MIN(StepWidth!G11:FR11))/MAX(StepWidth!G11:FR11) -> 59.492591 | BV11: =100*(MAX(StepWidth!G51:FR51)-MIN(StepWidth!G51:FR51))/MAX(StepWidth!G51:FR51) -> 56.925257 | BW11: =100*(MAX(Distance!H11:FR11)-MIN(Distance!H11:FR11))/MAX(Distance!H11:FR11) -> 93.41384 | BX11: =100*(MAX(Distance!H51:FR51)-MIN(Distance!H51:FR51))/MAX(Distance!H51:FR51) -> 100
A12: 11 | B12: o11 | C12: B | D12: F | E12: 78 | F12: 78 | G12: 160 | H12: 160 | I12: 6.2 | J12: -9.3 | K12: 26 | L12: 27.1 | M12: 26 | N12: 55.2 | O12: 0.277 | P12: 0.504 | Q12: 9.4 | R12: 31.1 | S12: 125 | T12: 116 | U12: 0.18192 | V12: 0.22113793 | W12: 0.30241935 | X12: 0.29773913 | Y12: 4.0992 | Z12: 6.075 | AA12: 7.0615786 | AB12: 9.3530009 | AC12: 2.0728264 | AD12: 1.9321562 | AE12: 0.13733973 | AF12: 0.20636381 | AG12: 14.137097 | AH12: 4.78 | AI12: 6.5048387 | AJ12: 16.304348 | AK12: 616.1336 | AL12: 710.87069 | AM12: 4.3986533 | AN12: 5.4926408 | AO12: 60.24 | AP12: 59.892 | AQ12: 0.48192 | AR12: 0.51631034 | AS12: =SLOPE(TFlight!G12:FR12,TPoints!G12:FR12) -> -0.00068664227 | AT12: =SLOPE(TFlight!G52:FR52,TPoints!G52:FR52) -> -0.0012187844 | AU12: =SLOPE(TContact!H12:FR12,TPoints!H12:FR12) -> 0.00036008798 | AV12: =SLOPE(TContact!H52:FR52,TPoints!H52:FR52) -> 0.00074154056 | AW12: =SLOPE(Elevation!G12:FR12,TPoints!G12:FR12) -> -0.030466696 | AX12: =SLOPE(Elevation!G52:FR52,TPoints!G52:FR52) -> -0.068890148 | AY12: =SLOPE(Power!H12:FR12,TPoints!H12:FR12) -> -0.038413553 | AZ12: =SLOPE(Power!H52:FR52,TPoints!H52:FR52) -> -0.086201385 | BA12: =SLOPE(Pace!H12:FR12,TPoints!H12:FR12) -> 0.0016305964 | BB12: =SLOPE(Pace!H52:FR52,TPoints!H52:FR52) -> 0.0016703545 | BC12: =SLOPE(RSI!H12:FR12,TPoints!H12:FR12) -> -0.0011186088 | BD12: =SLOPE(RSI!H52:FR52,TPoints!H52:FR52) -> -0.0029366151 | BE12: =SLOPE(StepWidth!G12:FR12,TPoints!G12:FR12) -> 1.0527018 | BF12: =SLOPE(StepWidth!G52:FR52,TPoints!G52:FR52) -> -3.2847776 | BG12: =SLOPE(Distance!H12:FR12,TPoints!H12:FR12) -> -0.017415017 | BH12: =SLOPE(Distance!H52:FR52,TPoints!H52:FR52) -> -0.0098515821 | BI12: =100*(MAX(TFlight!G12:FR12)-MIN(TFlight!G12:FR12))/MAX(TFlight!G12:FR12) -> 36.697248 | BJ12: =100*(MAX(TFlight!G52:FR52)-MIN(TFlight!G52:FR52))/MAX(TFlight!G52:FR52) -> 42.763158 | BK12: =100*(MAX(TContact!H12:FR12)-MIN(TContact!H12:FR12))/MAX(TContact!H12:FR12) -> 62.130178 | BL12: =100*(MAX(TContact!H52:FR52)-MIN(TContact!H52:FR52))/MAX(TContact!H52:FR52) -> 30.177515 | BM12: =100*(MAX(Elevation!G12:FR12)-MIN(Elevation!G12:FR12))/MAX(Elevation!G12:FR12) -> 60.344828 | BN12: =100*(MAX(Elevation!G52:FR52)-MIN(Elevation!G52:FR52))/MAX(Elevation!G52:FR52) -> 67.256637 | BO12: =100*(MAX(Power!H12:FR12)-MIN(Power!H12:FR12))/MAX(Power!H12:FR12) -> 56.246653 | BP12: =100*(MAX(Power!H52:FR52)-MIN(Power!H52:FR52))/MAX(Power!H52:FR52) -> 60.149348 | BQ12: =100*(MAX(Pace!H12:FR12)-MIN(Pace!H12:FR12))/MAX(Pace!H12:FR12) -> 45.96577 | BR12: =100*(MAX(Pace!H52:FR52)-MIN(Pace!H52:FR52))/MAX(Pace!H52:FR52) -> 18.245614 | BS12: =100*(MAX(RSI!H12:FR12)-MIN(RSI!H12:FR12))/MAX(RSI!H12:FR12) -> 82.656601 | BT12: =100*(MAX(RSI!H52:FR52)-MIN(RSI!H52:FR52))/MAX(RSI!H52:FR52) -> 74.945557 | BU12: =100*(MAX(StepWidth!G12:FR12)-MIN(StepWidth!G12:FR12))/MAX(StepWidth!G12:FR12) -> 45.236355 | BV12: =100*(MAX(StepWidth!G52:FR52)-MIN(StepWidth!G52:FR52))/MAX(StepWidth!G52:FR52) -> 57.561326 | BW12: =100*(MAX(Distance!H12:FR12)-MIN(Distance!H12:FR12))/MAX(Distance!H12:FR12) -> 100 | BX12: =100*(MAX(Distance!H52:FR52)-MIN(Distance!H52:FR52))/MAX(Distance!H52:FR52) -> 96.329741
A13: 12 | B13: o12 | C13: B | D13: F | E13: 88 | F13: 88 | G13: 160 | H13: 160 | I13: 7.3 | J13: -4.7 | K13: 26 | L13: 28.1 | M13: 31.3 | N13: 28.1 | O13: 0.277 | P13: 0.2 | Q13: 9.4 | R13: 4.9 | S13: 132 | T13: 118 | U13: 0.12589394 | V13: 0.063135593 | W13: 0.33071756 | X13: 0.42360684 | Y13: 1.9651515 | Z13: 0.54745763 | AA13: 4.2077691 | AB13: 1.8654734 | AC13: 2.1916768 | AD13: 2.2425806 | AE13: 0.060016777 | AF13: 0.01721374 | AG13: 3.2030534 | AH13: 6.6521368 | AI13: 6.9358779 | AJ13: 5.3641026 | AK13: 709.25227 | AL13: 754.13814 | AM13: 4.614301 | AN13: 4.9284358 | AO13: 59.942 | AP13: 57.012 | AQ13: 0.45410606 | AR13: 0.48315254 | AS13: =SLOPE(TFlight!G13:FR13,TPoints!G13:FR13) -> -0.00031521593 | AT13: =SLOPE(TFlight!G53:FR53,TPoints!G53:FR53) -> -0.00066312453 | AU13: =SLOPE(TContact!H13:FR13,TPoints!H13:FR13) -> 0.00047980646 | AV13: =SLOPE(TContact!H53:FR53,TPoints!H53:FR53) -> 0.0041380634 | AW13: =SLOPE(Elevation!G13:FR13,TPoints!G13:FR13) -> -0.0094050395 | AX13: =SLOPE(Elevation!G53:FR53,TPoints!G53:FR53) -> -0.009984918 | AY13: =SLOPE(Power!H13:FR13,TPoints!H13:FR13) -> -0.01525055 | AZ13: =SLOPE(Power!H53:FR53,TPoints!H53:FR53) -> -0.02566018 | BA13: =SLOPE(Pace!H13:FR13,TPoints!H13:FR13) -> -0.00075476283 | BB13: =SLOPE(Pace!H53:FR53,TPoints!H53:FR53) -> -0.008250327 | BC13: =SLOPE(RSI!H13:FR13,TPoints!H13:FR13) -> -0.00037421944 | BD13: =SLOPE(RSI!H53:FR53,TPoints!H53:FR53) -> -0.00043163219 | BE13: =SLOPE(StepWidth!G13:FR13,TPoints!G13:FR13) -> -5.9492063 | BF13: =SLOPE(StepWidth!G53:FR53,TPoints!G53:FR53) -> -5.9855322 | BG13: =SLOPE(Distance!H13:FR13,TPoints!H13:FR13) -> -0.011402827 | BH13: =SLOPE(Distance!H53:FR53,TPoints!H53:FR53) -> 0.06470855 | BI13: =100*(MAX(TFlight!G13:FR13)-MIN(TFlight!G13:FR13))/MAX(TFlight!G13:FR13) -> 48.809524 | BJ13: =100*(MAX(TFlight!G53:FR53)-MIN(TFlight!G53:FR53))/MAX(TFlight!G53:FR53) -> 89.090909 | BK13: =100*(MAX(TContact!H13:FR13)-MIN(TContact!H13:FR13))/MAX(TContact!H13:FR13) -> 19.892473 | BL13: =100*(MAX(TContact!H53:FR53)-MIN(TContact!H53:FR53))/MAX(TContact!H53:FR53) -> 99.013158 | BM13: =100*(MAX(Elevation!G13:FR13)-MIN(Elevation!G13:FR13))/MAX(Elevation!G13:FR13) -> 74.285714 | BN13: =100*(MAX(Elevation!G53:FR53)-MIN(Elevation!G53:FR53))/MAX(Elevation!G53:FR53) -> 100 | BO13: =100*(MAX(Power!H13:FR13)-MIN(Power!H13:FR13))/MAX(Power!H13:FR13) -> 59.093692 | BP13: =100*(MAX(Power!H53:FR53)-MIN(Power!H53:FR53))/MAX(Power!H53:FR53) -> 96.400824 | BQ13: =100*(MAX(Pace!H13:FR13)-MIN(Pace!H13:FR13))/MAX(Pace!H13:FR13) -> 11.934156 | BR13: =100*(MAX(Pace!H53:FR53)-MIN(Pace!H53:FR53))/MAX(Pace!H53:FR53) -> 95.294118 | BS13: =100*(MAX(RSI!H13:FR13)-MIN(RSI!H13:FR13))/MAX(RSI!H13:FR13) -> 78.360656 | BT13: =100*(MAX(RSI!H53:FR53)-MIN(RSI!H53:FR53))/MAX(RSI!H53:FR53) -> 100 | BU13: =100*(MAX(StepWidth!G13:FR13)-MIN(StepWidth!G13:FR13))/MAX(StepWidth!G13:FR13) -> 60.400542 | BV13: =100*(MAX(StepWidth!G53:FR53)-MIN(StepWidth!G53:FR53))/MAX(StepWidth!G53:FR53) -> 99.728641 | BW13: =100*(MAX(Distance!H13:FR13)-MIN(Distance!H13:FR13))/MAX(Distance!H13:FR13) -> 98.405096 | BX13: =100*(MAX(Distance!H53:FR53)-MIN(Distance!H53:FR53))/MAX(Distance!H53:FR53) -> 99.076997
... A41: 40 | B41: o40 | C41: J | D41: F | E41: 55 | F41: 55 | G41: 147 | H41: 147 | I41: -10.9 | J41: -3.1 | K41: 25 | L41: 27.1 | M41: 28.1 | N41: 27.1 | O41: 0.426 | P41: 0.368 | Q41: 22.2 | R41: 16.6 | S41: 118 | T41: 147 | U41: 0.23942373 | V41: 0.14919728 | W41: 0.27223932 | X41: 0.26039726 | Y41: 7.1322034 | Z41: 2.7823129 | AA41: 10.957723 | AB41: 5.6914029 | AC41: 1.9603038 | AD41: 2.4510086 | AE41: 0.26529278 | AF41: 0.10771954 | AG41: 2.7128205 | AH41: 5.9815068 | AI41: 9.8478632 | AJ41: 2.8157534 | AK41: 493.65254 | AL41: 446.78095 | AM41: 7.5123945 | AN41: 3.5393781 | AO41: 60.104 | AP41: 59.95 | AQ41: 0.50935593 | AR41: 0.40782313 | AS41: =SLOPE(TFlight!G41:FR41,TPoints!G41:FR41) -> -0.0011331148 | AT41: =SLOPE(TFlight!G81:FR81,TPoints!G81:FR81) -> -4.1667044e-05 | AU41: =SLOPE(TContact!H41:FR41,TPoints!H41:FR41) -> 0.00042057031 | AV41: =SLOPE(TContact!H81:FR81,TPoints!H81:FR81) -> 0.00030130441 | AW41: =SLOPE(Elevation!G41:FR41,TPoints!G41:FR41) -> -0.06717261 | AX41: =SLOPE(Elevation!G81:FR81,TPoints!G81:FR81) -> -0.0015953243 | AY41: =SLOPE(Power!H41:FR41,TPoints!H41:FR41) -> -0.084980325 | AZ41: =SLOPE(Power!H81:FR81,TPoints!H81:FR81) -> -0.0021742778 | BA41: =SLOPE(Pace!H41:FR41,TPoints!H41:FR41) -> 0.0028169641 | BB41: =SLOPE(Pace!H81:FR81,TPoints!H81:FR81) -> -0.0018786956 | BC41: =SLOPE(RSI!H41:FR41,TPoints!H41:FR41) -> -0.0029224724 | BD41: =SLOPE(RSI!H81:FR81,TPoints!H81:FR81) -> -0.00010983117 | BE41: =SLOPE(StepWidth!G41:FR41,TPoints!G41:FR41) -> -1.6112908 | BF41: =SLOPE(StepWidth!G81:FR81,TPoints!G81:FR81) -> 1.1986479 | BG41: =SLOPE(Distance!H41:FR41,TPoints!H41:FR41) -> -0.080952447 | BH41: =SLOPE(Distance!H81:FR81,TPoints!H81:FR81) -> -0.014688849 | BI41: =100*(MAX(TFlight!G41:FR41)-MIN(TFlight!G41:FR41))/MAX(TFlight!G41:FR41) -> 45.512821 | BJ41: =100*(MAX(TFlight!G81:FR81)-MIN(TFlight!G81:FR81))/MAX(TFlight!G81:FR81) -> 61.403509 | BK41: =100*(MAX(TContact!H41:FR41)-MIN(TContact!H41:FR41))/MAX(TContact!H41:FR41) -> 31.764706 | BL41: =100*(MAX(TContact!H81:FR81)-MIN(TContact!H81:FR81))/MAX(TContact!H81:FR81) -> 36.809816 | BM41: =100*(MAX(Elevation!G41:FR41)-MIN(Elevation!G41:FR41))/MAX(Elevation!G41:FR41) -> 70.588235 | BN41: =100*(MAX(Elevation!G81:FR81)-MIN(Elevation!G81:FR81))/MAX(Elevation!G81:FR81) -> 85.9375 | BO41: =100*(MAX(Power!H41:FR41)-MIN(Power!H41:FR41))/MAX(Power!H41:FR41) -> 63.199513 | BP41: =100*(MAX(Power!H81:FR81)-MIN(Power!H81:FR81))/MAX(Power!H81:FR81) -> 73.624538 | BQ41: =100*(MAX(Pace!H41:FR41)-MIN(Pace!H41:FR41))/MAX(Pace!H41:FR41) -> 24.482759 | BR41: =100*(MAX(Pace!H81:FR81)-MIN(Pace!H81:FR81))/MAX(Pace!H81:FR81) -> 26.406926 | BS41: =100*(MAX(RSI!H41:FR41)-MIN(RSI!H41:FR41))/MAX(RSI!H41:FR41) -> 78.337596 | BT41: =100*(MAX(RSI!H81:FR81)-MIN(RSI!H81:FR81))/MAX(RSI!H81:FR81) -> 86.941964 | BU41: =100*(MAX(StepWidth!G41:FR41)-MIN(StepWidth!G41:FR41))/MAX(StepWidth!G41:FR41) -> 57.531529 | BV41: =100*(MAX(StepWidth!G81:FR81)-MIN(StepWidth!G81:FR81))/MAX(StepWidth!G81:FR81) -> 56.00921 | BW41: =100*(MAX(Distance!H41:FR41)-MIN(Distance!H41:FR41))/MAX(Distance!H41:FR41) -> 97.537693 | BX41: =100*(MAX(Distance!H81:FR81)-MIN(Distance!H81:FR81))/MAX(Distance!H81:FR81) -> 94.955924

Sheet GeneralSt
A1: Index | B1: Name | C1: Test | D1: Group | E1: Sex | F1: Weight | G1: Height | H1: WPX1J | I1: StepWidth1J1 | J1: StepWidth1J2 | K1: TFlight1J | L1: Elevation1J | M1: NJumps | N1: TFlight | O1: TContact | P1: Elevation | Q1: Power | R1: Pace | S1: RSI | T1: WPX | U1: WPY | V1: StepWidth | W1: Distance | X1: TTotalSum | Y1: TTotalAvg | Z1: SlopeTF | AA1: SlopeTC | AB1: SlopeE | AC1: SlopePw | AD1: SlopePace | AE1: SlopeRSI | AF1: SlopeStepWidth | AG1: SlopeDistance | AH1: BoscoTFlight | AI1: BoscoTContact | AJ1: BoscoElevation | AK1: BoscoPower | AL1: BoscoPace | AM1: BoscoRSI | AN1: BoscoStepWidth | AO1: BoscoDistance
A2: 1 | B2: o1 | C2: Initial | D2: J | E2: F | F2: 69 | G2: 158 | H2: 1.1 | I2: 24 | J2: 27.1 | K2: 0.396 | L2: 19.2 | M2: 122 | N2: 0.18412295 | O2: 0.30944628 | P2: 4.3245902 | Q2: 7.4688274 | R2: 2.0526649 | S2: 0.15572703 | T2: 10.163636 | U2: 2.9793388 | V2: 501.20164 | W2: 5.5264096 | X2: 59.906 | Y2: 0.49103279 | Z2: =SLOPE(TFlight!G2:FR2,TPoints!G2:FR2) -> -0.0012364034 | AA2: =SLOPE(TContact!H2:FR2,TPoints!H2:FR2) -> 0.00026183766 | AB2: =SLOPE(Elevation!G2:FR2,TPoints!G2:FR2) -> -0.057057162 | AC2: =SLOPE(Power!H2:FR2,TPoints!H2:FR2) -> -0.069713536 | AD2: =SLOPE(Pace!H2:FR2,TPoints!H2:FR2) -> 0.0036433542 | AE2: =SLOPE(RSI!H2:FR2,TPoints!H2:FR2) -> -0.0020763793 | AF2: =SLOPE(StepWidth!G2:FR2,TPoints!G2:FR2) -> -1.481837 | AG2: =SLOPE(Distance!H2:FR2,TPoints!H2:FR2) -> -0.042946386 | AH2: =100*(MAX(TFlight!G2:FR2)-MIN(TFlight!G2:FR2))/MAX(TFlight!G2:FR2) -> 74.948665 | AI2: =100*(MAX(TContact!H2:FR2)-MIN(TContact!H2:FR2))/MAX(TContact!H2:FR2) -> 95.05814 | AJ2: =100*(MAX(Elevation!G2:FR2)-MIN(Elevation!G2:FR2))/MAX(Elevation!G2:FR2) -> 93.814433 | AK2: =100*(MAX(Power!H2:FR2)-MIN(Power!H2:FR2))/MAX(Power!H2:FR2) -> 91.533225 | AL2: =100*(MAX(Pace!H2:FR2)-MIN(Pace!H2:FR2))/MAX(Pace!H2:FR2) -> 76.448829 | AM2: =100*(MAX(RSI!H2:FR2)-MIN(RSI!H2:FR2))/MAX(RSI!H2:FR2) -> 97.581792 | AN2: =100*(MAX(StepWidth!G2:FR2)-MIN(StepWidth!G2:FR2))/MAX(StepWidth!G2:FR2) -> 84.515746 | AO2: =100*(MAX(Distance!H2:FR2)-MIN(Distance!H2:FR2))/MAX(Distance!H2:FR2) -> 94.867406
A3: 2 | B3: o2 | C3: Initial | D3: B | E3: M | F3: 70 | G3: 157 | H3: 0 | I3: 0 | J3: 42.7 | K3: 0.348 | L3: 14.8 | M3: 135 | N3: 0.18534815 | O3: 0.26132836 | P3: 4.3511111 | Q3: 7.7648689 | R3: 2.247888 | S3: 0.16911416 | T3: 3.9529851 | U3: 7.0470149 | V3: 778.53926 | W3: 7.5052544 | X3: 60.04 | Y3: 0.44474074 | Z3: =SLOPE(TFlight!G3:FR3,TPoints!G3:FR3) -> -0.0014249813 | AA3: =SLOPE(TContact!H3:FR3,TPoints!H3:FR3) -> 0.00038717841 | AB3: =SLOPE(Elevation!G3:FR3,TPoints!G3:FR3) -> -0.067642414 | AC3: =SLOPE(Power!H3:FR3,TPoints!H3:FR3) -> -0.092408945 | AD3: =SLOPE(Pace!H3:FR3,TPoints!H3:FR3) -> 0.0051172557 | AE3: =SLOPE(RSI!H3:FR3,TPoints!H3:FR3) -> -0.0029524293 | AF3: =SLOPE(StepWidth!G3:FR3,TPoints!G3:FR3) -> -1.8888534 | AG3: =SLOPE(Distance!H3:FR3,TPoints!H3:FR3) -> 0.014513489 | AH3: =100*(MAX(TFlight!G3:FR3)-MIN(TFlight!G3:FR3))/MAX(TFlight!G3:FR3) -> 58.695652 | AI3: =100*(MAX(TContact!H3:FR3)-MIN(TContact!H3:FR3))/MAX(TContact!H3:FR3) -> 30.718954 | AJ3: =100*(MAX(Elevation!G3:FR3)-MIN(Elevation!G3:FR3))/MAX(Elevation!G3:FR3) -> 82.795699 | AK3: =100*(MAX(Power!H3:FR3)-MIN(Power!H3:FR3))/MAX(Power!H3:FR3) -> 73.617815 | AL3: =100*(MAX(Pace!H3:FR3)-MIN(Pace!H3:FR3))/MAX(Pace!H3:FR3) -> 22.957198 | AM3: =100*(MAX(RSI!H3:FR3)-MIN(RSI!H3:FR3))/MAX(RSI!H3:FR3) -> 86.331399 | AN3: =100*(MAX(StepWidth!G3:FR3)-MIN(StepWidth!G3:FR3))/MAX(StepWidth!G3:FR3) -> 67.538708 | AO3: =100*(MAX(Distance!H3:FR3)-MIN(Distance!H3:FR3))/MAX(Distance!H3:FR3) -> 100
A4: 3 | B4: o3 | C4: Initial | D4: J | E4: F | F4: 67 | G4: 156 | H4: 5.8 | I4: 22.9 | J4: 43.8 | K4: 0.441 | L4: 23.8 | M4: 105 | N4: 0.27706667 | O4: 0.29490385 | P4: 9.5580952 | Q4: 13.118771 | R4: 1.7594164 | S4: 0.32950798 | T4: 9.2961538 | U4: 5.8153846 | V4: 732.44571 | W4: 11.384442 | X4: 59.762 | Y4: 0.5691619 | Z4: =SLOPE(TFlight!G4:FR4,TPoints!G4:FR4) -> -0.0013306825 | AA4: =SLOPE(TContact!H4:FR4,TPoints!H4:FR4) -> -0.00022116082 | AB4: =SLOPE(Elevation!G4:FR4,TPoints!G4:FR4) -> -0.084553303 | AC4: =SLOPE(Power!H4:FR4,TPoints!H4:FR4) -> -0.088587874 | AD4: =SLOPE(Pace!H4:FR4,TPoints!H4:FR4) -> 0.0045518142 | AE4: =SLOPE(RSI!H4:FR4,TPoints!H4:FR4) -> -0.0028536843 | AF4: =SLOPE(StepWidth!G4:FR4,TPoints!G4:FR4) -> 3.2431868 | AG4: =SLOPE(Distance!H4:FR4,TPoints!H4:FR4) -> -0.031273173 | AH4: =100*(MAX(TFlight!G4:FR4)-MIN(TFlight!G4:FR4))/MAX(TFlight!G4:FR4) -> 58.181818 | AI4: =100*(MAX(TContact!H4:FR4)-MIN(TContact!H4:FR4))/MAX(TContact!H4:FR4) -> 65.363128 | AJ4: =100*(MAX(Elevation!G4:FR4)-MIN(Elevation!G4:FR4))/MAX(Elevation!G4:FR4) -> 82.706767 | AK4: =100*(MAX(Power!H4:FR4)-MIN(Power!H4:FR4))/MAX(Power!H4:FR4) -> 73.815731 | AL4: =100*(MAX(Pace!H4:FR4)-MIN(Pace!H4:FR4))/MAX(Pace!H4:FR4) -> 54.618474 | AM4: =100*(MAX(RSI!H4:FR4)-MIN(RSI!H4:FR4))/MAX(RSI!H4:FR4) -> 87.306202 | AN4: =100*(MAX(StepWidth!G4:FR4)-MIN(StepWidth!G4:FR4))/MAX(StepWidth!G4:FR4) -> 52.590314 | AO4: =100*(MAX(Distance!H4:FR4)-MIN(Distance!H4:FR4))/MAX(Distance!H4:FR4) -> 100
A5: 4 | B5: o4 | C5: Initial | D5: B | E5: F | F5: 63 | G5: 151 | H5: -6.3 | I5: 24 | J5: 25 | K5: 0.352 | L5: 15.2 | M5: 122 | N5: 0.23113115 | O5: 0.26495868 | P5: 6.707377 | Q5: 10.580177 | R5: 2.0242633 | S5: 0.25670932 | T5: 6.1471074 | U5: 14.550413 | V5: 447.20164 | W5: 6.9325309 | X5: 60.258 | Y5: 0.49391803 | Z5: =SLOPE(TFlight!G5:FR5,TPoints!G5:FR5) -> -0.0010880268 | AA5: =SLOPE(TContact!H5:FR5,TPoints!H5:FR5) -> 0.00020250929 | AB5: =SLOPE(Elevation!G5:FR5,TPoints!G5:FR5) -> -0.062688248 | AC5: =SLOPE(Power!H5:FR5,TPoints!H5:FR5) -> -0.073324366 | AD5: =SLOPE(Pace!H5:FR5,TPoints!H5:FR5) -> 0.0033908977 | AE5: =SLOPE(RSI!H5:FR5,TPoints!H5:FR5) -> -0.0024366125 | AF5: =SLOPE(StepWidth!G5:FR5,TPoints!G5:FR5) -> -0.5049609 | AG5: =SLOPE(Distance!H5:FR5,TPoints!H5:FR5) -> -0.0016277799 | AH5: =100*(MAX(TFlight!G5:FR5)-MIN(TFlight!G5:FR5))/MAX(TFlight!G5:FR5) -> 51.851852 | AI5: =100*(MAX(TContact!H5:FR5)-MIN(TContact!H5:FR5))/MAX(TContact!H5:FR5) -> 30.434783 | AJ5: =100*(MAX(Elevation!G5:FR5)-MIN(Elevation!G5:FR5))/MAX(Elevation!G5:FR5) -> 76.744186 | AK5: =100*(MAX(Power!H5:FR5)-MIN(Power!H5:FR5))/MAX(Power!H5:FR5) -> 68.315392 | AL5: =100*(MAX(Pace!H5:FR5)-MIN(Pace!H5:FR5))/MAX(Pace!H5:FR5) -> 26.804124 | AM5: =100*(MAX(RSI!H5:FR5)-MIN(RSI!H5:FR5))/MAX(RSI!H5:FR5) -> 81.36646 | AN5: =100*(MAX(StepWidth!G5:FR5)-MIN(StepWidth!G5:FR5))/MAX(StepWidth!G5:FR5) -> 66.662015 | AO5: =100*(MAX(Distance!H5:FR5)-MIN(Distance!H5:FR5))/MAX(Distance!H5:FR5) -> 99.452045
A6: 5 | B6: o5 | C6: Initial | D6: J | E6: M | F6: 58 | G6: 146 | H6: 6.8 | I6: 24 | J6: 47.9 | K6: 0.437 | L6: 23.4 | M6: 104 | N6: 0.29269231 | O6: 0.28415534 | P6: 10.629808 | Q6: 14.446068 | R6: 1.7386097 | S6: 0.37799077 | T6: 9.2563107 | U6: 10.61165 | V6: 623.32019 | W6: 9.1813938 | X6: 59.708 | Y6: 0.57411538 | Z6: =SLOPE(TFlight!G6:FR6,TPoints!G6:FR6) -> -0.0012340379 | AA6: =SLOPE(TContact!H6:FR6,TPoints!H6:FR6) -> 0.00033848779 | AB6: =SLOPE(Elevation!G6:FR6,TPoints!G6:FR6) -> -0.087679877 | AC6: =SLOPE(Power!H6:FR6,TPoints!H6:FR6) -> -0.101877 | AD6: =SLOPE(Pace!H6:FR6,TPoints!H6:FR6) -> 0.0027668923 | AE6: =SLOPE(RSI!H6:FR6,TPoints!H6:FR6) -> -0.003642162 | AF6: =SLOPE(StepWidth!G6:FR6,TPoints!G6:FR6) -> 1.0193617 | AG6: =SLOPE(Distance!H6:FR6,TPoints!H6:FR6) -> -0.05657095 | AH6: =100*(MAX(TFlight!G6:FR6)-MIN(TFlight!G6:FR6))/MAX(TFlight!G6:FR6) -> 46.511628 | AI6: =100*(MAX(TContact!H6:FR6)-MIN(TContact!H6:FR6))/MAX(TContact!H6:FR6) -> 32.58427 | AJ6: =100*(MAX(Elevation!G6:FR6)-MIN(Elevation!G6:FR6))/MAX(Elevation!G6:FR6) -> 71.034483 | AK6: =100*(MAX(Power!H6:FR6)-MIN(Power!H6:FR6))/MAX(Power!H6:FR6) -> 63.398195 | AL6: =100*(MAX(Pace!H6:FR6)-MIN(Pace!H6:FR6))/MAX(Pace!H6:FR6) -> 27.743902 | AM6: =100*(MAX(RSI!H6:FR6)-MIN(RSI!H6:FR6))/MAX(RSI!H6:FR6) -> 75.522098 | AN6: =100*(MAX(StepWidth!G6:FR6)-MIN(StepWidth!G6:FR6))/MAX(StepWidth!G6:FR6) -> 59.559819 | AO6: =100*(MAX(Distance!H6:FR6)-MIN(Distance!H6:FR6))/MAX(Distance!H6:FR6) -> 98.367612
A7: 6 | B7: o6 | C7: Initial | D7: B | E7: M | F7: 59 | G7: 149 | H7: 2 | I7: 24 | J7: 22.9 | K7: 0.324 | L7: 12.9 | M7: 144 | N7: 0.17319444 | O7: 0.24577622 | P7: 3.7819444 | Q7: 7.3377124 | R7: 2.4222812 | S7: 0.16155303 | T7: 8.3573427 | U7: 6.7104895 | V7: 461.00833 | W7: 5.7043799 | X7: 60.086 | Y7: 0.41726389 | Z7: =SLOPE(TFlight!G7:FR7,TPoints!G7:FR7) -> -0.00045430103 | AA7: =SLOPE(TContact!H7:FR7,TPoints!H7:FR7) -> -0.00072134029 | AB7: =SLOPE(Elevation!G7:FR7,TPoints!G7:FR7) -> -0.018629115 | AC7: =SLOPE(Power!H7:FR7,TPoints!H7:FR7) -> -0.024643129 | AD7: =SLOPE(Pace!H7:FR7,TPoints!H7:FR7) -> 0.0045972866 | AE7: =SLOPE(RSI!H7:FR7,TPoints!H7:FR7) -> -0.00067268364 | AF7: =SLOPE(StepWidth!G7:FR7,TPoints!G7:FR7) -> -0.8807157 | AG7: =SLOPE(Distance!H7:FR7,TPoints!H7:FR7) -> -0.024558802 | AH7: =100*(MAX(TFlight!G7:FR7)-MIN(TFlight!G7:FR7))/MAX(TFlight!G7:FR7) -> 54.411765 | AI7: =100*(MAX(TContact!H7:FR7)-MIN(TContact!H7:FR7))/MAX(TContact!H7:FR7) -> 84.163701 | AJ7: =100*(MAX(Elevation!G7:FR7)-MIN(Elevation!G7:FR7))/MAX(Elevation!G7:FR7) -> 79.120879 | AK7: =100*(MAX(Power!H7:FR7)-MIN(Power!H7:FR7))/MAX(Power!H7:FR7) -> 69.262168 | AL7: =100*(MAX(Pace!H7:FR7)-MIN(Pace!H7:FR7))/MAX(Pace!H7:FR7) -> 74.277017 | AM7: =100*(MAX(RSI!H7:FR7)-MIN(RSI!H7:FR7))/MAX(RSI!H7:FR7) -> 90.583822 | AN7: =100*(MAX(StepWidth!G7:FR7)-MIN(StepWidth!G7:FR7))/MAX(StepWidth!G7:FR7) -> 68.182347 | AO7: =100*(MAX(Distance!H7:FR7)-MIN(Distance!H7:FR7))/MAX(Distance!H7:FR7) -> 96.246479
A8: 7 | B8: o7 | C8: Initial | D8: B | E8: M | F8: 50 | G8: 139 | H8: -8.3 | I8: 24 | J8: 28.1 | K8: 0.343 | L8: 14.4 | M8: 125 | N8: 0.226608 | O8: 0.2548871 | P8: 6.5736 | Q8: 10.796044 | R8: 2.1053886 | S8: 0.27186773 | T8: 19.176613 | U8: 18.567742 | V8: 568.2856 | W8: 9.7233426 | X8: 59.932 | Y8: 0.479456 | Z8: =SLOPE(TFlight!G8:FR8,TPoints!G8:FR8) -> -0.00076993923 | AA8: =SLOPE(TContact!H8:FR8,TPoints!H8:FR8) -> 0.0010976802 | AB8: =SLOPE(Elevation!G8:FR8,TPoints!G8:FR8) -> -0.037853796 | AC8: =SLOPE(Power!H8:FR8,TPoints!H8:FR8) -> -0.065554966 | AD8: =SLOPE(Pace!H8:FR8,TPoints!H8:FR8) -> 0.00050749082 | AE8: =SLOPE(RSI!H8:FR8,TPoints!H8:FR8) -> -0.0023044388 | AF8: =SLOPE(StepWidth!G8:FR8,TPoints!G8:FR8) -> 4.6707936 | AG8: =SLOPE(Distance!H8:FR8,TPoints!H8:FR8) -> 0.03876446 | AH8: =100*(MAX(TFlight!G8:FR8)-MIN(TFlight!G8:FR8))/MAX(TFlight!G8:FR8) -> 90.419162 | AI8: =100*(MAX(TContact!H8:FR8)-MIN(TContact!H8:FR8))/MAX(TContact!H8:FR8) -> 77.230047 | AJ8: =100*(MAX(Elevation!G8:FR8)-MIN(Elevation!G8:FR8))/MAX(Elevation!G8:FR8) -> 99.270073 | AK8: =100*(MAX(Power!H8:FR8)-MIN(Power!H8:FR8))/MAX(Power!H8:FR8) -> 95.752843 | AL8: =100*(MAX(Pace!H8:FR8)-MIN(Pace!H8:FR8))/MAX(Pace!H8:FR8) -> 70.676692 | AM8: =100*(MAX(RSI!H8:FR8)-MIN(RSI!H8:FR8))/MAX(RSI!H8:FR8) -> 99.490332 | AN8: =100*(MAX(StepWidth!G8:FR8)-MIN(StepWidth!G8:FR8))/MAX(StepWidth!G8:FR8) -> 76.742526 | AO8: =100*(MAX(Distance!H8:FR8)-MIN(Distance!H8:FR8))/MAX(Distance!H8:FR8) -> 98.509063
A9: 8 | B9: o8 | C9: Initial | D9: B | E9: F | F9: 62 | G9: 150 | H9: 3.6 | I9: 25 | J9: 27.1 | K9: 0.356 | L9: 15.5 | M9: 167 | N9: 0.14863473 | O9: 0.21239759 | P9: 2.8041916 | Q9: 6.2489169 | R9: 2.782822 | S9: 0.1358733 | T9: 5.2439759 | U9: 10.383735 | V9: 533.3485 | W9: 4.9613023 | X9: 60.08 | Y9: 0.35976048 | Z9: =SLOPE(TFlight!G9:FR9,TPoints!G9:FR9) -> -0.00067424035 | AA9: =SLOPE(TContact!H9:FR9,TPoints!H9:FR9) -> 0.00050254337 | AB9: =SLOPE(Elevation!G9:FR9,TPoints!G9:FR9) -> -0.025847364 | AC9: =SLOPE(Power!H9:FR9,TPoints!H9:FR9) -> -0.048890743 | AD9: =SLOPE(Pace!H9:FR9,TPoints!H9:FR9) -> 0.001452834 | AE9: =SLOPE(RSI!H9:FR9,TPoints!H9:FR9) -> -0.0016059533 | AF9: =SLOPE(StepWidth!G9:FR9,TPoints!G9:FR9) -> 0.68330806 | AG9: =SLOPE(Distance!H9:FR9,TPoints!H9:FR9) -> 0.0049770575 | AH9: =100*(MAX(TFlight!G9:FR9)-MIN(TFlight!G9:FR9))/MAX(TFlight!G9:FR9) -> 66.972477 | AI9: =100*(MAX(TContact!H9:FR9)-MIN(TContact!H9:FR9))/MAX(TContact!H9:FR9) -> 38.888889 | AJ9: =100*(MAX(Elevation!G9:FR9)-MIN(Elevation!G9:FR9))/MAX(Elevation!G9:FR9) -> 89.655172 | AK9: =100*(MAX(Power!H9:FR9)-MIN(Power!H9:FR9))/MAX(Power!H9:FR9) -> 79.607843 | AL9: =100*(MAX(Pace!H9:FR9)-MIN(Pace!H9:FR9))/MAX(Pace!H9:FR9) -> 32.579186 | AM9: =100*(MAX(RSI!H9:FR9)-MIN(RSI!H9:FR9))/MAX(RSI!H9:FR9) -> 91.578947 | AN9: =100*(MAX(StepWidth!G9:FR9)-MIN(StepWidth!G9:FR9))/MAX(StepWidth!G9:FR9) -> 57.268433 | AO9: =100*(MAX(Distance!H9:FR9)-MIN(Distance!H9:FR9))/MAX(Distance!H9:FR9) -> 100
A10: 9 | B10: o9 | C10: Initial | D10: B | E10: M | F10: 73 | G10: 156 | H10: 4.2 | I10: 24 | J10: 30.2 | K10: 0.406 | L10: 20.2 | M10: 147 | N10: 0.11587755 | O10: 0.294 | P10: 1.7530612 | Q10: 3.9713112 | R10: 2.4788886 | S10: 0.060800359 | T10: 9.559589 | U10: 13.228082 | V10: 829.02313 | W10: 4.1755014 | X10: 59.958 | Y10: 0.40787755 | Z10: =SLOPE(TFlight!G10:FR10,TPoints!G10:FR10) -> -0.00092493018 | AA10: =SLOPE(TContact!H10:FR10,TPoints!H10:FR10) -> 2.9047345e-05 | AB10: =SLOPE(Elevation!G10:FR10,TPoints!G10:FR10) -> -0.030113658 | AC10: =SLOPE(Power!H10:FR10,TPoints!H10:FR10) -> -0.039547261 | AD10: =SLOPE(Pace!H10:FR10,TPoints!H10:FR10) -> 0.0052935873 | AE10: =SLOPE(RSI!H10:FR10,TPoints!H10:FR10) -> -0.00093040311 | AF10: =SLOPE(StepWidth!G10:FR10,TPoints!G10:FR10) -> -4.5605151 | AG10: =SLOPE(Distance!H10:FR10,TPoints!H10:FR10) -> 0.022242472 | AH10: =100*(MAX(TFlight!G10:FR10)-MIN(TFlight!G10:FR10))/MAX(TFlight!G10:FR10) -> 84.126984 | AI10: =100*(MAX(TContact!H10:FR10)-MIN(TContact!H10:FR10))/MAX(TContact!H10:FR10) -> 70.605187 | AJ10: =100*(MAX(Elevation!G10:FR10)-MIN(Elevation!G10:FR10))/MAX(Elevation!G10:FR10) -> 97.435897 | AK10: =100*(MAX(Power!H10:FR10)-MIN(Power!H10:FR10))/MAX(Power!H10:FR10) -> 90.904018 | AL10: =100*(MAX(Pace!H10:FR10)-MIN(Pace!H10:FR10))/MAX(Pace!H10:FR10) -> 55.858311 | AM10: =100*(MAX(RSI!H10:FR10)-MIN(RSI!H10:FR10))/MAX(RSI!H10:FR10) -> 98.898988 | AN10: =100*(MAX(StepWidth!G10:FR10)-MIN(StepWidth!G10:FR10))/MAX(StepWidth!G10:FR10) -> 63.315195 | AO10: =100*(MAX(Distance!H10:FR10)-MIN(Distance!H10:FR10))/MAX(Distance!H10:FR10) -> 98.611956
A11: 10 | B11: o10 | C11: Initial | D11: J | E11: F | F11: 67 | G11: 158 | H11: 6.7 | I11: 26 | J11: 26 | K11: 0.461 | L11: 26.1 | M11: 114 | N11: 0.22185965 | O11: 0.30663717 | P11: 6.1342105 | Q11: 9.3209724 | R11: 1.89643 | S11: 0.20393189 | T11: 10.309735 | U11: 3.9964602 | V11: 699.25789 | W11: 7.3488496 | X11: 59.942 | Y11: 0.52580702 | Z11: =SLOPE(TFlight!G11:FR11,TPoints!G11:FR11) -> -0.00061808464 | AA11: =SLOPE(TContact!H11:FR11,TPoints!H11:FR11) -> 0.0001870422 | AB11: =SLOPE(Elevation!G11:FR11,TPoints!G11:FR11) -> -0.036761698 | AC11: =SLOPE(Power!H11:FR11,TPoints!H11:FR11) -> -0.040952864 | AD11: =SLOPE(Pace!H11:FR11,TPoints!H11:FR11) -> 0.0013749525 | AE11: =SLOPE(RSI!H11:FR11,TPoints!H11:FR11) -> -0.0013891652 | AF11: =SLOPE(StepWidth!G11:FR11,TPoints!G11:FR11) -> 0.55922474 | AG11: =SLOPE(Distance!H11:FR11,TPoints!H11:FR11) -> 0.021503282 | AH11: =100*(MAX(TFlight!G11:FR11)-MIN(TFlight!G11:FR11))/MAX(TFlight!G11:FR11) -> 48.101266 | AI11: =100*(MAX(TContact!H11:FR11)-MIN(TContact!H11:FR11))/MAX(TContact!H11:FR11) -> 36.787565 | AJ11: =100*(MAX(Elevation!G11:FR11)-MIN(Elevation!G11:FR11))/MAX(Elevation!G11:FR11) -> 72.95082 | AK11: =100*(MAX(Power!H11:FR11)-MIN(Power!H11:FR11))/MAX(Power!H11:FR11) -> 67.779376 | AL11: =100*(MAX(Pace!H11:FR11)-MIN(Pace!H11:FR11))/MAX(Pace!H11:FR11) -> 15.789474 | AM11: =100*(MAX(RSI!H11:FR11)-MIN(RSI!H11:FR11))/MAX(RSI!H11:FR11) -> 82.901554 | AN11: =100*(MAX(StepWidth!G11:FR11)-MIN(StepWidth!G11:FR11))/MAX(StepWidth!G11:FR11) -> 59.492591 | AO11: =100*(MAX(Distance!H11:FR11)-MIN(Distance!H11:FR11))/MAX(Distance!H11:FR11) -> 93.41384
A12: 11 | B12: o11 | C12: Initial | D12: B | E12: F | F12: 78 | G12: 160 | H12: 6.2 | I12: 26 | J12: 26 | K12: 0.277 | L12: 9.4 | M12: 125 | N12: 0.18192 | O12: 0.30241935 | P12: 4.0992 | Q12: 7.0615786 | R12: 2.0728264 | S12: 0.13733973 | T12: 14.137097 | U12: 6.5048387 | V12: 616.1336 | W12: 4.3986533 | X12: 60.24 | Y12: 0.48192 | Z12: =SLOPE(TFlight!G12:FR12,TPoints!G12:FR12) -> -0.00068664227 | AA12: =SLOPE(TContact!H12:FR12,TPoints!H12:FR12) -> 0.00036008798 | AB12: =SLOPE(Elevation!G12:FR12,TPoints!G12:FR12) -> -0.030466696 | AC12: =SLOPE(Power!H12:FR12,TPoints!H12:FR12) -> -0.038413553 | AD12: =SLOPE(Pace!H12:FR12,TPoints!H12:FR12) -> 0.0016305964 | AE12: =SLOPE(RSI!H12:FR12,TPoints!H12:FR12) -> -0.0011186088 | AF12: =SLOPE(StepWidth!G12:FR12,TPoints!G12:FR12) -> 1.0527018 | AG12: =SLOPE(Distance!H12:FR12,TPoints!H12:FR12) -> -0.017415017 | AH12: =100*(MAX(TFlight!G12:FR12)-MIN(TFlight!G12:FR12))/MAX(TFlight!G12:FR12) -> 36.697248 | AI12: =100*(MAX(TContact!H12:FR12)-MIN(TContact!H12:FR12))/MAX(TContact!H12:FR12) -> 62.130178 | AJ12: =100*(MAX(Elevation!G12:FR12)-MIN(Elevation!G12:FR12))/MAX(Elevation!G12:FR12) -> 60.344828 | AK12: =100*(MAX(Power!H12:FR12)-MIN(Power!H12:FR12))/MAX(Power!H12:FR12) -> 56.246653 | AL12: =100*(MAX(Pace!H12:FR12)-MIN(Pace!H12:FR12))/MAX(Pace!H12:FR12) -> 45.96577 | AM12: =100*(MAX(RSI!H12:FR12)-MIN(RSI!H12:FR12))/MAX(RSI!H12:FR12) -> 82.656601 | AN12: =100*(MAX(StepWidth!G12:FR12)-MIN(StepWidth!G12:FR12))/MAX(StepWidth!G12:FR12) -> 45.236355 | AO12: =100*(MAX(Distance!H12:FR12)-MIN(Distance!H12:FR12))/MAX(Distance!H12:FR12) -> 100
